Workbook
Name 공통과학: 과목목록!$E$68:$E$71
Name 공통국어: 과목목록!$E$4:$E$5
Name 공통사회: 과목목록!$E$45:$E$48
Name 공통수학: 과목목록!$E$15:$E$18
Name 공통영어: 과목목록!$E$30:$E$33
Name 과목명: 과목목록!$E$4:$E$200
Name 과목명열: [1]작업처리3!$BK$5:$BK$254
Name 과목유형: [1]작업처리1!$G$3:$G$7
Name 교과군: [1]작업처리1!$F$3:$F$13
Name 교과군표시: [1]작업처리1!$L$3:$L$13
Name 교과선택개수: [1]작업처리1!$E$3:$E$14
Name 교차집중: [1]작업처리1!$C$3:$C$11
Name 그외교육과정: [1]작업처리1!$H$3:$H$7
Name 데이터구분: [1]작업처리1!$R$3:$R$4
Name 데이터범위: [1]작업처리2!$B$4:$Y$253
Name 데이터열: [1]작업처리2!$B$3:$Y$3
Name 데이터행: [1]작업처리2!$A$4:$A$253
Name 석차등급: [1]작업처리1!$Q$3:$Q$5
Name 선택교과: [1]작업처리1!$D$3:$D$39
Name 성취도: [1]작업처리1!$M$3:$M$6
Name 여부: [1]작업처리1!$N$3:$N$4
Name 역사선택: 과목목록!$E$50,과목목록!$E$55,과목목록!$E$63
Name 연도목록: OFFSET([1]작업처리1!$S$3,0,0,COUNTA([1]작업처리1!$S:$S)-2,1)
Name 원데이터랭크: [1]작업처리3!$BM$5:$BM$254
Name 원데이터범위: [1]작업처리3!$R$5:$AG$254
Name 원데이터열: [1]작업처리3!$R$3:$AG$3
Name 융합선택과학: 과목목록!$E$84:$E$86
Name 융합선택교양: 과목목록!$E$156:$E$157
Name 융합선택국어: 과목목록!$E$12:$E$14
Name 융합선택기술·가정_정보: 과목목록!$E$109:$E$113
Name 융합선택사회: 과목목록!$E$62:$E$67
Name 융합선택수학: 과목목록!$E$27:$E$29
Name 융합선택영어: 과목목록!$E$42:$E$44
Name 융합선택예술: 과목목록!$E$101:$E$102
Name 융합선택제2외국어_한문: 과목목록!$E$140:$E$147
Name 융합선택체육: 과목목록!$E$92:$E$93
Name 일반선택과학: 과목목록!$E$72:$E$75
Name 일반선택교양: 과목목록!$E$148:$E$149
Name 일반선택국어: 과목목록!$E$6:$E$8
Name 일반선택기술·가정_정보: 과목목록!$E$103:$E$104
Name 일반선택사회: 과목목록!$E$49:$E$52
Name 일반선택수학: 과목목록!$E$19:$E$21
Name 일반선택영어: 과목목록!$E$34:$E$36
Name 일반선택예술: 과목목록!$E$94:$E$96
Name 일반선택제2외국어_한문: 과목목록!$E$114:$E$122
Name 일반선택체육: 과목목록!$E$87:$E$88
Name 점검: [1]작업처리1!$O$3:$O$5
Name 진로선택과학: 과목목록!$E$76:$E$83
Name 진로선택교양: 과목목록!$E$150:$E$155
Name 진로선택국어: 과목목록!$E$9:$E$11
Name 진로선택기술·가정_정보: 과목목록!$E$105:$E$108
Name 진로선택사회: 과목목록!$E$53:$E$61
Name 진로선택수학: 과목목록!$E$22:$E$26
Name 진로선택영어: 과목목록!$E$37:$E$41
Name 진로선택예술: 과목목록!$E$97:$E$100
Name 진로선택제2외국어_한문: 과목목록!$E$123:$E$139
Name 진로선택체육: 과목목록!$E$89:$E$91
Name 추가과목유형: [1]학교정보!$T$8:$T$107
Name 추가교과군: [1]학교정보!$S$8:$S$107
Name 학년목록: [1]작업처리1!$T$3:$T$5

Sheet 과목목록
A1: 과목정보
A2: 과목정보 | F2: 학점정보 | I2: 성적 산출 정보 | O2: 추가
A3: 연번 | B3: 교과(군) | C3: 교과(군)2 | D3: 과목유형 | E3: 과목명 | F3: 기준학점 | G3: 최소 | H3: 최대 | I3: 성취도 | J3: 석차등급 | K3: 성취도별 분포비율 | L3: 원점수 | M3: 과목평균 | N3: 수강자수 | O3: 비고 | Q3: 현재 과목 정리 현황 | S3: =SUM(S4:S200) -> 154
A4: 1 | B4: 국어 | C4: 국어 | D4: 공통 | E4: 공통국어1 | F4: 4 | G4: 3 | H4: 4 | I4: 5단계 | J4: O | K4: O | L4: O | M4: O | N4: O | Q4: 국어 | R4: 공통 | S4: =COUNTIFS($B$4:$B$303,Q4,$D$4:$D$303,R4) -> 2
A5: 2 | B5: 국어 | C5: 국어 | D5: 공통 | E5: 공통국어2 | F5: 4 | G5: 3 | H5: 4 | I5: 5단계 | J5: O | K5: O | L5: O | M5: O | N5: O | R5: 일반선택 | S5: =COUNTIFS($B$4:$B$303,Q4,$D$4:$D$303,R5) -> 3
A6: 3 | B6: 국어 | C6: 국어 | D6: 일반선택 | E6: 화법과 언어 | F6: 4 | G6: 3 | H6: 5 | I6: 5단계 | J6: O | K6: O | L6: O | M6: O | N6: O | R6: 진로선택 | S6: =COUNTIFS($B$4:$B$303,Q4,$D$4:$D$303,R6) -> 3
A7: 4 | B7: 국어 | C7: 국어 | D7: 일반선택 | E7: 독서와 작문 | F7: 4 | G7: 3 | H7: 5 | I7: 5단계 | J7: O | K7: O | L7: O | M7: O | N7: O | R7: 융합선택 | S7: =COUNTIFS($B$4:$B$303,Q4,$D$4:$D$303,R7) -> 3
A8: 5 | B8: 국어 | C8: 국어 | D8: 일반선택 | E8: 문학 | F8: 4 | G8: 3 | H8: 5 | I8: 5단계 | J8: O | K8: O | L8: O | M8: O | N8: O | Q8: 수학 | R8: 공통 | S8: =COUNTIFS($B$4:$B$303,Q8,$D$4:$D$303,R8) -> 4
A9: 6 | B9: 국어 | C9: 국어 | D9: 진로선택 | E9: 주제 탐구 독서 | F9: 4 | G9: 3 | H9: 5 | I9: 5단계 | J9: O | K9: O | L9: O | M9: O | N9: O | R9: 일반선택 | S9: =COUNTIFS($B$4:$B$303,Q8,$D$4:$D$303,R9) -> 3
A10: 7 | B10: 국어 | C10: 국어 | D10: 진로선택 | E10: 문학과 영상 | F10: 4 | G10: 3 | H10: 5 | I10: 5단계 | J10: O | K10: O | L10: O | M10: O | N10: O | R10: 진로선택 | S10: =COUNTIFS($B$4:$B$303,Q8,$D$4:$D$303,R10) -> 5
A11: 8 | B11: 국어 | C11: 국어 | D11: 진로선택 | E11: 직무 의사소통 | F11: 4 | G11: 3 | H11: 5 | I11: 5단계 | J11: O | K11: O | L11: O | M11: O | N11: O | R11: 융합선택 | S11: =COUNTIFS($B$4:$B$303,Q8,$D$4:$D$303,R11) -> 3
A12: 9 | B12: 국어 | C12: 국어 | D12: 융합선택 | E12: 독서 토론과 글쓰기 | F12: 4 | G12: 3 | H12: 5 | I12: 5단계 | J12: O | K12: O | L12: O | M12: O | N12: O | Q12: 영어 | R12: 공통 | S12: =COUNTIFS($B$4:$B$303,Q12,$D$4:$D$303,R12) -> 4
A13: 10 | B13: 국어 | C13: 국어 | D13: 융합선택 | E13: 매체 의사소통 | F13: 4 | G13: 3 | H13: 5 | I13: 5단계 | J13: O | K13: O | L13: O | M13: O | N13: O | R13: 일반선택 | S13: =COUNTIFS($B$4:$B$303,Q12,$D$4:$D$303,R13) -> 3
A14: 11 | B14: 국어 | C14: 국어 | D14: 융합선택 | E14: 언어생활 탐구 | F14: 4 | G14: 3 | H14: 5 | I14: 5단계 | J14: O | K14: O | L14: O | M14: O | N14: O | R14: 진로선택 | S14: =COUNTIFS($B$4:$B$303,Q12,$D$4:$D$303,R14) -> 5
A15: 12 | B15: 수학 | C15: 수학 | D15: 공통 | E15: 공통수학1 | F15: 4 | G15: 3 | H15: 4 | I15: 5단계 | J15: O | K15: O | L15: O | M15: O | N15: O | R15: 융합선택 | S15: =COUNTIFS($B$4:$B$303,Q12,$D$4:$D$303,R15) -> 3
A16: 13 | B16: 수학 | C16: 수학 | D16: 공통 | E16: 공통수학2 | F16: 4 | G16: 3 | H16: 4 | I16: 5단계 | J16: O | K16: O | L16: O | M16: O | N16: O | Q16: 사회(역사/도덕포함) | R16: 공통 | S16: =COUNTIFS($B$4:$B$303,Q16,$D$4:$D$303,R16) -> 4
A17: 14 | B17: 수학 | C17: 수학 | D17: 공통 | E17: 기본수학1 | F17: 4 | G17: 3 | H17: 4 | I17: 5단계 | J17: O | K17: O | L17: O | M17: O | N17: O | R17: 일반선택 | S17: =COUNTIFS($B$4:$B$303,Q16,$D$4:$D$303,R17) -> 4
A18: 15 | B18: 수학 | C18: 수학 | D18: 공통 | E18: 기본수학2 | F18: 4 | G18: 3 | H18: 4 | I18: 5단계 | J18: O | K18: O | L18: O | M18: O | N18: O | R18: 진로선택 | S18: =COUNTIFS($B$4:$B$303,Q16,$D$4:$D$303,R18) -> 9
A19: 16 | B19: 수학 | C19: 수학 | D19: 일반선택 | E19: 대수 | F19: 4 | G19: 3 | H19: 5 | I19: 5단계 | J19: O | K19: O | L19: O | M19: O | N19: O | R19: 융합선택 | S19: =COUNTIFS($B$4:$B$303,Q16,$D$4:$D$303,R19) -> 6
A20: 17 | B20: 수학 | C20: 수학 | D20: 일반선택 | E20: 미적분Ⅰ | F20: 4 | G20: 3 | H20: 5 | I20: 5단계 | J20: O | K20: O | L20: O | M20: O | N20: O | Q20: 과학 | R20: 공통 | S20: =COUNTIFS($B$4:$B$303,Q20,$D$4:$D$303,R20) -> 4
A21: 18 | B21: 수학 | C21: 수학 | D21: 일반선택 | E21: 확률과 통계 | F21: 4 | G21: 3 | H21: 5 | I21: 5단계 | J21: O | K21: O | L21: O | M21: O | N21: O | R21: 일반선택 | S21: =COUNTIFS($B$4:$B$303,Q20,$D$4:$D$303,R21) -> 4
A22: 19 | B22: 수학 | C22: 수학 | D22: 진로선택 | E22: 기하 | F22: 4 | G22: 3 | H22: 5 | I22: 5단계 | J22: O | K22: O | L22: O | M22: O | N22: O | R22: 진로선택 | S22: =COUNTIFS($B$4:$B$303,Q20,$D$4:$D$303,R22) -> 8
A23: 20 | B23: 수학 | C23: 수학 | D23: 진로선택 | E23: 미적분Ⅱ | F23: 4 | G23: 3 | H23: 5 | I23: 5단계 | J23: O | K23: O | L23: O | M23: O | N23: O | R23: 융합선택 | S23: =COUNTIFS($B$4:$B$303,Q20,$D$4:$D$303,R23) -> 3
A24: 21 | B24: 수학 | C24: 수학 | D24: 진로선택 | E24: 경제 수학 | F24: 4 | G24: 3 | H24: 5 | I24: 5단계 | J24: O | K24: O | L24: O | M24: O | N24: O | Q24: 체육 | R24: 공통 | S24: =COUNTIFS($B$4:$B$303,Q24,$D$4:$D$303,R24) -> 0
A25: 22 | B25: 수학 | C25: 수학 | D25: 진로선택 | E25: 인공지능 수학 | F25: 4 | G25: 3 | H25: 5 | I25: 5단계 | J25: O | K25: O | L25: O | M25: O | N25: O | R25: 일반선택 | S25: =COUNTIFS($B$4:$B$303,Q24,$D$4:$D$303,R25) -> 2
A26: 23 | B26: 수학 | C26: 수학 | D26: 진로선택 | E26: 직무 수학 | F26: 4 | G26: 3 | H26: 5 | I26: 5단계 | J26: O | K26: O | L26: O | M26: O | N26: O | R26: 진로선택 | S26: =COUNTIFS($B$4:$B$303,Q24,$D$4:$D$303,R26) -> 3
A27: 24 | B27: 수학 | C27: 수학 | D27: 융합선택 | E27: 수학과 문화 | F27: 4 | G27: 3 | H27: 5 | I27: 5단계 | J27: O | K27: O | L27: O | M27: O | N27: O | R27: 융합선택 | S27: =COUNTIFS($B$4:$B$303,Q24,$D$4:$D$303,R27) -> 2
A28: 25 | B28: 수학 | C28: 수학 | D28: 융합선택 | E28: 실용 통계 | F28: 4 | G28: 3 | H28: 5 | I28: 5단계 | J28: O | K28: O | L28: O | M28: O | N28: O | Q28: 예술 | R28: 공통 | S28: =COUNTIFS($B$4:$B$303,Q28,$D$4:$D$303,R28) -> 0
A29: 26 | B29: 수학 | C29: 수학 | D29: 융합선택 | E29: 수학과제 탐구 | F29: 4 | G29: 3 | H29: 5 | I29: 5단계 | J29: O | K29: O | L29: O | M29: O | N29: O | R29: 일반선택 | S29: =COUNTIFS($B$4:$B$303,Q28,$D$4:$D$303,R29) -> 3
A30: 27 | B30: 영어 | C30: 영어 | D30: 공통 | E30: 공통영어1 | F30: 4 | G30: 3 | H30: 4 | I30: 5단계 | J30: O | K30: O | L30: O | M30: O | N30: O | R30: 진로선택 | S30: =COUNTIFS($B$4:$B$303,Q28,$D$4:$D$303,R30) -> 4
A31: 28 | B31: 영어 | C31: 영어 | D31: 공통 | E31: 공통영어2 | F31: 4 | G31: 3 | H31: 4 | I31: 5단계 | J31: O | K31: O | L31: O | M31: O | N31: O | R31: 융합선택 | S31: =COUNTIFS($B$4:$B$303,Q28,$D$4:$D$303,R31) -> 2
A32: 29 | B32: 영어 | C32: 영어 | D32: 공통 | E32: 기본영어1 | F32: 4 | G32: 3 | H32: 4 | I32: 5단계 | J32: O | K32: O | L32: O | M32: O | N32: O | Q32: 기술⋅가정/정보 | R32: 공통 | S32: =COUNTIFS($B$4:$B$303,Q32,$D$4:$D$303,R32) -> 0
A33: 30 | B33: 영어 | C33: 영어 | D33: 공통 | E33: 기본영어2 | F33: 4 | G33: 3 | H33: 4 | I33: 5단계 | J33: O | K33: O | L33: O | M33: O | N33: O | R33: 일반선택 | S33: =COUNTIFS($B$4:$B$303,Q32,$D$4:$D$303,R33) -> 2
A34: 31 | B34: 영어 | C34: 영어 | D34: 일반선택 | E34: 영어Ⅰ | F34: 4 | G34: 3 | H34: 5 | I34: 5단계 | J34: O | K34: O | L34: O | M34: O | N34: O | R34: 진로선택 | S34: =COUNTIFS($B$4:$B$303,Q32,$D$4:$D$303,R34) -> 4
A35: 32 | B35: 영어 | C35: 영어 | D35: 일반선택 | E35: 영어Ⅱ | F35: 4 | G35: 3 | H35: 5 | I35: 5단계 | J35: O | K35: O | L35: O | M35: O | N35: O | R35: 융합선택 | S35: =COUNTIFS($B$4:$B$303,Q32,$D$4:$D$303,R35) -> 5
A36: 33 | B36: 영어 | C36: 영어 | D36: 일반선택 | E36: 영어 독해와 작문 | F36: 4 | G36: 3 | H36: 5 | I36: 5단계 | J36: O | K36: O | L36: O | M36: O | N36: O | Q36: 제2외국어/한문 | R36: 공통 | S36: =COUNTIFS($B$4:$B$303,Q36,$D$4:$D$303,R36) -> 0
A37: 34 | B37: 영어 | C37: 영어 | D37: 진로선택 | E37: 영미 문학 읽기 | F37: 4 | G37: 3 | H37: 5 | I37: 5단계 | J37: O | K37: O | L37: O | M37: O | N37: O | R37: 일반선택 | S37: =COUNTIFS($B$4:$B$303,Q36,$D$4:$D$303,R37) -> 9
A38: 35 | B38: 영어 | C38: 영어 | D38: 진로선택 | E38: 영어 발표와 토론 | F38: 4 | G38: 3 | H38: 5 | I38: 5단계 | J38: O | K38: O | L38: O | M38: O | N38: O | R38: 진로선택 | S38: =COUNTIFS($B$4:$B$303,Q36,$D$4:$D$303,R38) -> 17
A39: 36 | B39: 영어 | C39: 영어 | D39: 진로선택 | E39: 심화 영어 | F39: 4 | G39: 3 | H39: 5 | I39: 5단계 | J39: O | K39: O | L39: O | M39: O | N39: O | R39: 융합선택 | S39: =COUNTIFS($B$4:$B$303,Q36,$D$4:$D$303,R39) -> 8
A40: 37 | B40: 영어 | C40: 영어 | D40: 진로선택 | E40: 심화 영어 독해와 작문 | F40: 4 | G40: 3 | H40: 5 | I40: 5단계 | J40: O | K40: O | L40: O | M40: O | N40: O | Q40: 교양 | R40: 공통 | S40: =COUNTIFS($B$4:$B$303,Q40,$D$4:$D$303,R40) -> 0
...
